#Cpp 

# 1. 异常
异常是程序在执行期间产生的问题。C++ 异常是指在程序运行时发生的特殊情况，比如尝试除以零的操作。
异常提供了一种转移程序控制权的方式。C++ 异常处理涉及到三个关键字：`try`、`catch`、`throw`。
-   **throw:**  当问题出现时，程序会抛出一个异常。这是通过使用 `throw` 关键字来完成的。
-   **catch:**  在您想要处理问题的地方，通过异常处理程序捕获异常。`catch` 关键字用于捕获异常。
-   **try:** `try` 块中的代码标识将被激活的特定异常。它后面通常跟着一个或多个 `catch` 块。

例如在除法运算中，被除数为0:
```cpp
double divide(double x, double y)
{
    return x/y;
}

int main(){
    cout << divide(10 , 0) << endl;
    return 0;
}
```

输出：
```cpp
inf
```

```cpp
/********* try catch 使用语法 ***********/
try
{
   // 保护代码
} catch( ExceptionName e1 )
{
   // catch 块
} catch( ExceptionName e2 )
{
   // catch 块
} catch( ExceptionName eN )
{
   // catch 块
}
```

示例：
```cpp
double divide(double x, double y)
{
    if (y == 0.0f)
    {
        /* 抛出的异常可以是多种类型 
           可以是字符串、char、int值... 
           一旦触发异常 程序就会抛出，后面的程序就会中断不再执行 */ 
        throw "throw exception";
    }
    return x/y;
}


int main(){
    // 使用 try 语句块内置需要判断程序异常的语句。
    try {
        cout << divide(10 , 0) << endl;
    }
    catch(const char* str)
    {
        cout << str << endl;
    }
    catch(int num)
    {
        cout << num << endl;
    }
    // 类似switch 的default，省略throw的其他情况
    catch (...)
    {
        cout << "exception" << endl;
    }

    return 0;
}
```
输出：
```txt
throw exception
```
一般异常处理的代码在开发中较少使用，一般在测试的时候会使用。


# 2. 自定义异常

|异常|	描述|
| --- | --- |
|`std::exception`	    |该异常是所有标准 C++ 异常的父类。|
|`std::bad_alloc`	    |该异常可以通过 new 抛出。|
|`std::bad_cast	`    |该异常可以通过 dynamic_cast 抛出。|
|`std::bad_typeid`	|该异常可以通过 typeid 抛出。|
|`std::bad_exception`	|这在处理 C++ 程序中无法预期的异常时非常有用。|
|`std::logic_error`	|理论上可以通过读取代码来检测到的异常。|
|`std::domain_error`	|当使用了一个无效的数学域时，会抛出该异常。|
|`std::invalid_argument`	|当使用了无效的参数时，会抛出该异常。|
|`std::length_error`	|当创建了太长的 `std::string` 时，会抛出该异常。|
|`std::out_of_range`	|该异常可以通过方法抛出，例如 `std::vector` 和 `std::bitset<>::operator[]()`。|
|`std::runtime_error`	|理论上不可以通过读取代码来检测到的异常。|
|`std::overflow_error`	|当发生数学上溢时，会抛出该异常。|
|`std::range_error`	|当尝试存储超出范围的值时，会抛出该异常。|
|`std::underflow_error`	|当发生数学下溢时，会抛出该异常。|


**继承关系**：
![C++异常 exception](img/C++异常%20exception.png)

示例：
```cpp
#include <iostream>
#include <exception>
using namespace std;

class MyException : public exception
{
public:
    const char * what () const throw ()
    {
        return "C++ Exception";
    }
};
 
int main(){
    try
    {
        throw MyException();
    }
    catch(MyException& obj)
    {
        cout << "MyException caught" << endl;
        cout << obj.what() << endl;
    }
    catch(...)
    {
        // 其他的错误
    }
    return 0;
}
```

输出：
```txt
MyException caught
C++ Exception
```

